<?xml version="1.0" ?>
<!-- =================================================================================== -->
<!-- |    This document was autogenerated by xacro from /home/user/ros2_ws/src/athens_moveit_config/config/athens.urdf.xacro | -->
<!-- |    EDITING THIS FILE BY HAND IS NOT RECOMMENDED                                 | -->
<!-- =================================================================================== -->
<robot name="athens">
  <link name="base_link">
    <visual>
      <origin rpy="0 0 0" xyz="0 0 0.25"/>
      <geometry>
        <cylinder length="0.5" radius="0.1"/>
      </geometry>
      <material name="blue">
        <color rgba="0 0 1 1"/>
      </material>
    </visual>
    <collision>
      <origin rpy="0 0 0" xyz="0 0 0.25"/>
      <geometry>
        <cylinder length="0.5" radius="0.1"/>
      </geometry>
    </collision>
    <inertial>
      <origin rpy="0 0 0" xyz="0 0 0.25"/>
      <mass value="1.0"/>
      <inertia ixx="0.0233" ixy="0" ixz="0" iyy="0.0233" iyz="0" izz="0.005"/>
    </inertial>
  </link>
  <link name="arm_0_link">
    <visual>
      <origin rpy="0 0 0" xyz="0 0 0.2"/>
      <geometry>
        <cylinder length="0.4" radius="0.05"/>
      </geometry>
      <material name="red">
        <color rgba="1 0 0 1"/>
      </material>
    </visual>
    <collision>
      <origin rpy="0 0 0" xyz="0 0 0.2"/>
      <geometry>
        <cylinder length="0.4" radius="0.05"/>
      </geometry>
    </collision>
    <inertial>
      <origin rpy="0 0 0" xyz="0 0 0.2"/>
      <mass value="0.8"/>
      <inertia ixx="0.0112" ixy="0" ixz="0" iyy="0.0112" iyz="0" izz="0.001"/>
    </inertial>
  </link>
  <link name="arm_1_link">
    <visual>
      <origin rpy="0 0 0" xyz="0 0 0.2"/>
      <geometry>
        <cylinder length="0.4" radius="0.05"/>
      </geometry>
      <material name="blue">
        <color rgba="0 0 1 1"/>
      </material>
    </visual>
    <collision>
      <origin rpy="0 0 0" xyz="0 0 0.2"/>
      <geometry>
        <cylinder length="0.4" radius="0.05"/>
      </geometry>
    </collision>
    <inertial>
      <origin rpy="0 0 0" xyz="0 0 0.2"/>
      <mass value="0.8"/>
      <inertia ixx="0.0112" ixy="0" ixz="0" iyy="0.0112" iyz="0" izz="0.001"/>
    </inertial>
  </link>
  <link name="arm_2_link">
    <visual>
      <origin rpy="0 0 0" xyz="0 0 0.2"/>
      <geometry>
        <cylinder length="0.4" radius="0.05"/>
      </geometry>
      <material name="red">
        <color rgba="1 0 0 1"/>
      </material>
    </visual>
    <collision>
      <origin rpy="0 0 0" xyz="0 0 0.2"/>
      <geometry>
        <cylinder length="0.4" radius="0.05"/>
      </geometry>
    </collision>
    <inertial>
      <origin rpy="0 0 0" xyz="0 0 0.2"/>
      <mass value="0.8"/>
      <inertia ixx="0.0112" ixy="0" ixz="0" iyy="0.0112" iyz="0" izz="0.001"/>
    </inertial>
  </link>
  <link name="gripper_base_link">
    <visual>
      <geometry>
        <box size="0.1 0.1 0.05"/>
      </geometry>
      <material name="grey">
        <color rgba="0.5 0.5 0.5 1"/>
      </material>
    </visual>
    <collision>
      <geometry>
        <box size="0.1 0.1 0.05"/>
      </geometry>
    </collision>
    <inertial>
      <mass value="0.2"/>
      <inertia ixx="0.000208" ixy="0" ixz="0" iyy="0.000208" iyz="0" izz="0.000333"/>
    </inertial>
  </link>
  <link name="gripper_1_link">
    <visual>
      <geometry>
        <box size="0.02 0.05 0.1"/>
      </geometry>
      <material name="grey">
        <color rgba="0.5 0.5 0.5 1"/>
      </material>
    </visual>
    <collision>
      <geometry>
        <box size="0.02 0.05 0.1"/>
      </geometry>
    </collision>
    <inertial>
      <mass value="0.05"/>
      <inertia ixx="0.0000458" ixy="0" ixz="0" iyy="0.0000433" iyz="0" izz="0.0000125"/>
    </inertial>
  </link>
  <link name="gripper_2_link">
    <visual>
      <geometry>
        <box size="0.02 0.05 0.1"/>
      </geometry>
      <material name="grey">
        <color rgba="0.5 0.5 0.5 1"/>
      </material>
    </visual>
    <collision>
      <geometry>
        <box size="0.02 0.05 0.1"/>
      </geometry>
    </collision>
    <inertial>
      <mass value="0.05"/>
      <inertia ixx="0.0000458" ixy="0" ixz="0" iyy="0.0000433" iyz="0" izz="0.0000125"/>
    </inertial>
  </link>
  <joint name="arm_0_joint" type="revolute">
    <parent link="base_link"/>
    <child link="arm_0_link"/>
    <origin rpy="0 0 0" xyz="0 0 0.5"/>
    <axis xyz="0 1 0"/>
    <limit effort="10" lower="-1.57" upper="1.57" velocity="1"/>
  </joint>
  <joint name="arm_1_joint" type="revolute">
    <parent link="arm_0_link"/>
    <child link="arm_1_link"/>
    <origin rpy="0 0 0" xyz="0 0 0.4"/>
    <axis xyz="0 1 0"/>
    <limit effort="10" lower="-1.57" upper="1.57" velocity="1"/>
  </joint>
  <joint name="arm_2_joint" type="revolute">
    <parent link="arm_1_link"/>
    <child link="arm_2_link"/>
    <origin rpy="0 0 0" xyz="0 0 0.4"/>
    <axis xyz="0 1 0"/>
    <limit effort="10" lower="-1.57" upper="1.57" velocity="1"/>
  </joint>
  <joint name="gripper_base_joint" type="fixed">
    <parent link="arm_2_link"/>
    <child link="gripper_base_link"/>
    <origin rpy="0 0 0" xyz="0 0 0.425"/>
  </joint>
  <joint name="gripper_1_joint" type="prismatic">
    <parent link="gripper_base_link"/>
    <child link="gripper_1_link"/>
    <origin rpy="0 0 0" xyz="0.04 0 0.07"/>
    <axis xyz="1 0 0"/>
    <limit effort="10" lower="0" upper="0.05" velocity="0.1"/>
  </joint>
  <joint name="gripper_2_joint" type="prismatic">
    <parent link="gripper_base_link"/>
    <child link="gripper_2_link"/>
    <origin rpy="0 0 0" xyz="-0.04 0 0.07"/>
    <axis xyz="-1 0 0"/>
    <limit effort="10" lower="0" upper="0.05" velocity="0.1"/>
  </joint>
  <ros2_control name="FakeSystem" type="system">
    <hardware>
      <!-- By default, set up controllers for simulation. This won't work on real hardware -->
      <plugin>gz_ros2_control/GenericSystem</plugin>
    </hardware>
    <joint name="arm_0_joint">
      <command_interface name="position"/>
      <state_interface name="position">
        <param name="initial_value">0</param>
      </state_interface>
      <state_interface name="velocity"/>
    </joint>
    <joint name="arm_1_joint">
      <command_interface name="position"/>
      <state_interface name="position">
        <param name="initial_value">0</param>
      </state_interface>
      <state_interface name="velocity"/>
    </joint>
    <joint name="arm_2_joint">
      <command_interface name="position"/>
      <state_interface name="position">
        <param name="initial_value">0</param>
      </state_interface>
      <state_interface name="velocity"/>
    </joint>
    <joint name="gripper_1_joint">
      <command_interface name="position"/>
      <state_interface name="position">
        <param name="initial_value">0</param>
      </state_interface>
      <state_interface name="velocity"/>
    </joint>
    <joint name="gripper_2_joint">
      <command_interface name="position"/>
      <state_interface name="position">
        <param name="initial_value">0</param>
      </state_interface>
      <state_interface name="velocity"/>
    </joint>
  </ros2_control>
  <gazebo>
    <plugin filename="libgz_ros2_control-system.so" name="gz_ros2_control::GazeboSimROS2ControlPlugin">
      <parameters>/home/user/ros2_ws/install/athens_moveit_config/share/athens_moveit_config/config/ros2_controllers.yaml</parameters>
      <controller_manager_name>controller_manager</controller_manager_name>
    </plugin>
  </gazebo>
</robot>
